Workbook

Sheet Cover
B12: Financial Analysis Model
B14: Table of Contents:
C16: Financial Statements
C18: Ratios
C20: 3-Step DuPont
C22: 5-Step DuPont
C25: Disclaimer:
C26: The following workbook and each cell in it has been protected using a password. It has been done so to preserve the formatting, formulas
C27: and ultimately the dynamicity of the model.
C28: If need be, suggestions and reviews can be made via E-Mail and Linkedin.
C29: Thank You, Have a Nice Day

Sheet Financial Statements
B8: Income Statement
B10: All figures in INR Crores unless stated | J10: 2019 | K10: 2020 | L10: 2021 | M10: 2022 | N10: 2023 | O10: 2024
B12: Revenue | J12: =DATA!C6 -> 146463 | K12: =DATA!D6 -> 156949 | L12: =DATA!E6 -> 164177 | M12: =DATA!F6 -> 191754 | N12: =DATA!G6 -> 225458 | O12: =DATA!H6 -> 240893
B13: COGS | J13: =-SUM(DATA!C10:C12, DATA!C14:C17) -> -83509 | K13: =-SUM(DATA!D10:D12, DATA!D14:D17) -> -89635 | L13: =-SUM(DATA!E10:E12, DATA!E14:E17) -> -94053 | M13: =-SUM(DATA!F10:F12, DATA!F14:F17) -> -111053 | N13: =-SUM(DATA!G10:G12, DATA!G14:G17) -> -132448 | O13: =-SUM(DATA!H10:H12, DATA!H14:H17) -> -139775
B14: Gross Profit | J14: =SUM(J12:J13) -> 62954 | K14: =SUM(K12:K13) -> 67314 | L14: =SUM(L12:L13) -> 70124 | M14: =SUM(M12:M13) -> 80701 | N14: =SUM(N12:N13) -> 93010 | O14: =SUM(O12:O13) -> 101118
B17: SG&A | J17: =-SUM(DATA!C24:C26, DATA!C28:C31) -> -23449 | K17: =-SUM(DATA!D24:D26, DATA!D28:D31) -> -25204 | L17: =-SUM(DATA!E24:E26, DATA!E28:E31) -> -23578 | M17: =-SUM(DATA!F24:F26, DATA!F28:F31) -> -27644 | N17: =-SUM(DATA!G24:G26, DATA!G28:G31) -> -33750 | O17: =-SUM(DATA!H24:H26, DATA!H28:H31) -> -36823
B18: EBITDA | J18: =SUM(J14,J17) -> 39505 | K18: =SUM(K14,K17) -> 42110 | L18: =SUM(L14,L17) -> 46546 | M18: =SUM(M14,M17) -> 53057 | N18: =SUM(N14,N17) -> 59260 | O18: =SUM(O14,O17) -> 64295
B21: Depreciation and Amortisation | J21: =-SUM(DATA!C13,DATA!C27) -> -2055 | K21: =-SUM(DATA!D13,DATA!D27) -> -3530 | L21: =-SUM(DATA!E13,DATA!E27) -> -4065 | M21: =-SUM(DATA!F13,DATA!F27) -> -4604 | N21: =-SUM(DATA!G13,DATA!G27) -> -5023 | O21: =-SUM(DATA!H13,DATA!H27) -> -4984
B22: Other Income/(Expenses) | J22: =DATA!C36 -> 4113 | K22: =DATA!D36 -> 3668 | L22: =DATA!E36 -> 2497 | M22: =DATA!F36 -> 3234 | N22: =DATA!G36 -> 2670 | O22: =DATA!H36 -> 3727
B23: EBIT | J23: =SUM(J18, J21:J22) -> 41563 | K23: =SUM(K18, K21:K22) -> 42248 | L23: =SUM(L18, L21:L22) -> 44978 | M23: =SUM(M18, M21:M22) -> 51687 | N23: =SUM(N18, N21:N22) -> 56907 | O23: =SUM(O18, O21:O22) -> 63038
B26: Interest Expense | J26: =DATA!C45 -> -90 | K26: =DATA!D45 -> -107 | L26: =DATA!E45 -> -132 | M26: =DATA!F45 -> -122 | N26: =DATA!G45 -> -156 | O26: =DATA!H45 -> -191
B27: Interest Income | J27: 0 | K27: 0 | L27: 0 | M27: 0 | N27: 0 | O27: 0
B28: Exceptional Expense | J28: 0 | K28: 0 | L28: 0 | M28: 0 | N28: 0 | O28: 0
B29: EBT | J29: =SUM(J23, J26:J28) -> 41473 | K29: =SUM(K23, K26:K28) -> 42141 | L29: =SUM(L23, L26:L28) -> 44846 | M29: =SUM(M23, M26:M28) -> 51565 | N29: =SUM(N23, N26:N28) -> 56751 | O29: =SUM(O23, O26:O28) -> 62847
B32: Current Tax | J32: =-DATA!C40 -> -10001 | K32: =-DATA!D40 -> -9801 | L32: =-DATA!E40 -> -11458 | M32: =-DATA!F40 -> -13238 | N32: =-DATA!G40 -> -14604 | O32: =-DATA!H40 -> -16262
B33: Total Tax | J33: =SUM(J32) -> -10001 | K33: =SUM(K32) -> -9801 | L33: =SUM(L32) -> -11458 | M33: =SUM(M32) -> -13238 | N33: =SUM(N32) -> -14604 | O33: =SUM(O32) -> -16262
B36: Net Income | J36: =SUM(J29, J33) -> 31472 | K36: =SUM(K29, K33) -> 32340 | L36: =SUM(L29, L33) -> 33388 | M36: =SUM(M29, M33) -> 38327 | N36: =SUM(N29, N33) -> 42147 | O36: =SUM(O29, O33) -> 46585
B38: No of Equity Shares | J38: 375.24 | K38: 375.24 | L38: 369.91 | M38: 365.91 | N38: 365.91 | O38: 361.81
B39: Earning per Share | J39: =J36 / J38 -> 83.871655 | K39: =K36 / K38 -> 86.184842 | L39: =L36 / L38 -> 90.259793 | M39: =M36 / M38 -> 104.74434 | N39: =N36 / N38 -> 115.18406 | O39: =O36 / O38 -> 128.75542
B41: Dividends | J41: =I115 + J36 - J115 -> 27111 | K41: =J115 + K36 - K115 -> 39023 | L41: =K115 + L36 - L115 -> 32575 | M41: =L115 + M36 - M115 -> 40023 | N41: =M115 + N36 - N115 -> 45602 | O41: =N115 + O36 - O115 -> 51253
B44: Cash Flow Statement
B46: All figures in INR Crores unless stated | J46: 2019 | K46: 2020 | L46: 2021 | M46: 2022 | N46: 2023 | O46: 2024
B48: CASH FROM OPERATING
B49: Net Income | J49: =J36 -> 31472 | K49: =K36 -> 32340 | L49: =L36 -> 33388 | M49: =M36 -> 38327 | N49: =N36 -> 42147 | O49: =O36 -> 46585
B50: Depreciation | J50: =-J21 -> 2055 | K50: =-K21 -> 3530 | L50: =-L21 -> 4065 | M50: =-M21 -> 4604 | N50: =-N21 -> 5023 | O50: =-O21 -> 4984
B51: Cash From Accounts Receivable | J51: =I89 - J89 -> -874 | K51: =J89 - K89 -> -3761 | L51: =K89 - L89 -> -398 | M51: =L89 - M89 -> -5148 | N51: =M89 - N89 -> -8144 | O51: =N89 - O89 -> -3623
B52: Change in Other Current Assets | J52: =I90 - J90 -> -7692 | K52: =J90 - K90 -> 7077 | L52: =K90 - L90 -> -10433 | M52: =L90 - M90 -> 1748 | N52: =M90 - N90 -> 819 | O52: =N90 - O90 -> 2802
B53: Cash From Accounts Payable | J53: =J102 - I102 -> 1198 | K53: =K102 - J102 -> 448 | L53: =L102 - K102 -> 1120 | M53: =M102 - L102 -> 185 | N53: =N102 - M102 -> 2470 | O53: =O102 - N102 -> -534
B54: Cash From Other Current Liabilities | J54: =J103 - I103 -> 3058 | K54: =K103 - J103 -> 4528 | L54: =L103 - K103 -> 5975 | M54: =M103 - L103 -> 8011 | N54: =N103 - M103 -> -1263 | O54: =O103 - N103 -> 3080
B55: Other Adjustments | J55: -2212 | K55: 4137 | L55: -2100 | M55: -347 | N55: -640 | O55: -55
B56: Subtotal | J56: =SUM(J49:J55) -> 27005 | K56: =SUM(K49:K55) -> 48299 | L56: =SUM(L49:L55) -> 31617 | M56: =SUM(M49:M55) -> 47380 | N56: =SUM(N49:N55) -> 40412 | O56: =SUM(O49:O55) -> 53239
B59: CASH FROM INVESTING
B60: Capital Expenditure | J60: =I93 - J93 -> -50 | K60: =J93 - K93 -> -288 | L60: =K93 - L93 -> -197 | M60: =L93 - M93 -> 55 | N60: =M93 - N93 -> 485 | O60: =N93 - O93 -> 371
B61: Cash from Other Non-Current Assets | J61: =I94-J94 -> 2313 | K61: =J94-K94 -> -7566 | L61: =K94-L94 -> -628 | M61: =L94-M94 -> -1778 | N61: =M94-N94 -> -660 | O61: =N94-O94 -> -460
B62: Subtotal | J62: =SUM(J60:J61) -> 2263 | K62: =SUM(K60:K61) -> -7854 | L62: =SUM(L60:L61) -> -825 | M62: =SUM(M60:M61) -> -1723 | N62: =SUM(N60:N61) -> -175 | O62: =SUM(O60:O61) -> -89
B65: CASH FROM FINANCING
B66: Dividends | J66: =-J41 -> -27111 | K66: =-K41 -> -39023 | L66: =-L41 -> -32575 | M66: =-M41 -> -40023 | N66: =-N41 -> -45602 | O66: =-O41 -> -51253
B67: Change in Share Capital | J67: =J112 - I112 -> 184 | K67: =K112 - J112 -> 0 | L67: =L112 - K112 -> -5 | M67: =M112 - L112 -> -4 | N67: =N112 - M112 -> 0 | O67: =O112 - N112 -> -4
B68: Change in Share Premium | J68: =J113 - I113 -> 0 | K68: =K113 - J113 -> 0 | L68: =L113 - K113 -> 0 | M68: =M113 - L113 -> 0 | N68: =N113 - M113 -> 0 | O68: =O113 - N113 -> 0
B69: Subtotal | J69: =SUM(J66:J68) -> -26927 | K69: =SUM(K66:K68) -> -39023 | L69: =SUM(L66:L68) -> -32580 | M69: =SUM(M66:M68) -> -40027 | N69: =SUM(N66:N68) -> -45602 | O69: =SUM(O66:O68) -> -51257
...

Sheet DATA
A1: TCS Consolidated Income Statement as per IFRS - INR Mn | B1: FY18 | C1: FY19 | D1: FY20 | E1: FY21 | F1: FY22 | G1: FY23 | H1: FY24
E2: EX-ADJ *** | H2: EX-ADJ ****
A3: Revenue
A4: Information Technology and Consultancy Services | B4: 123104 | C4: 146463 | D4: 156949 | E4: 164177 | F4: 191754 | G4: 225458 | H4: 240893 | J4: 10
A5: Sale of Equipment and Software Licenses | B5: 0 | C5: 0 | D5: 0 | E5: 0 | F5: 0 | G5: 0 | H5: 0
A6: Total Revenue | B6: 123104 | C6: 146463 | D6: 156949 | E6: 164177 | F6: 191754 | G6: 225458 | H6: 240893 | K6: Dividends: | L6: 2018 | M6: 2019 | N6: 2020 | O6: 2021 | P6: 2022 | Q6: 2023 | R6: 2024
B7: 0 | C7: 0 | D7: 0 | E7: 0 | F7: 0 | G7: 0 | H7: 0 | M7: 11424 | N7: 37634 | O7: 10850 | P7: 13317 | Q7: 41347 | R7: 25137
A8: Cost of Revenues | B8: 0 | C8: 0 | D8: 0 | E8: 0 | F8: 0 | G8: 0 | H8: 0
A9: Cost of Services | B9: 0 | C9: 0 | D9: 0 | E9: 0 | F9: 0 | G9: 0 | H9: 0
A10: Employee Cost | B10: 50350 | C10: 60553 | D10: 65652 | E10: 71946 | F10: 84135 | G10: 99147 | H10: 109244
A11: Fees to External Consultants | B11: 8431 | C11: 10686 | D11: 12500 | E11: 12648 | F11: 16795 | G11: 20642 | H11: 14986
A12: Cost of Equipment and Software Licenses | B12: 2700 | C12: 2270 | D12: 1905 | E12: 1462 | F12: 1163 | G12: 1881 | H12: 3702
A13: Depreciation | B13: 1573 | C13: 1649 | D13: 2687 | E13: 3085 | F13: 3568 | G13: 3820 | H13: 3820
A14: Travel | B14: 1876 | C14: 2334 | D14: 2291 | E14: 883 | F14: 1294 | G14: 1815 | H14: 2059
A15: Communication | B15: 791 | C15: 984 | D15: 1232 | E15: 1434 | F15: 1537 | G15: 1500 | H15: 1475
A16: Facility Expenses | B16: 2646 | C16: 2984 | D16: 1798 | E16: 1401 | F16: 1354 | G16: 1651 | H16: 1926
A17: Other Costs | B17: 2921 | C17: 3698 | D17: 4257 | E17: 4279 | F17: 4775 | G17: 5812 | H17: 6383
A18: Total Cost of Revenues | B18: 71288 | C18: 85158 | D18: 92322 | E18: 97138 | F18: 114621 | G18: 136268 | H18: 143595
B19: 0 | C19: 0 | D19: 0 | E19: 0 | F19: 0 | G19: 0 | H19: 0
A20: Gross Profit | B20: 51816 | C20: 61305 | D20: 64627 | E20: 67039 | F20: 77133 | G20: 89190 | H20: 97298
B21: 0 | C21: 0 | D21: 0 | E21: 0 | F21: 0 | G21: 0 | H21: 0
A22: Operating Expenses | B22: 0 | C22: 0 | D22: 0 | E22: 0 | F22: 0 | G22: 0 | H22: 0
A23: Selling, General and Administrative Expenses | B23: 0 | C23: 0 | D23: 0 | E23: 0 | F23: 0 | G23: 0 | H23: 0
A24: Employee Cost | B24: 16046 | C24: 17692 | D24: 20300 | E24: 19868 | F24: 23419 | G24: 28375 | H24: 30888
A25: Fees to External Consultants | B25: 559 | C25: 644 | D25: 437 | E25: 569 | F25: 615 | G25: 693 | H25: 834
A26: Provision for Doubtful Debts | B26: 208 | C26: 187 | D26: 144 | E26: 201 | F26: 135 | G26: 139 | H26: 114
A27: Depreciation | B27: 441 | C27: 406 | D27: 843 | E27: 980 | F27: 1036 | G27: 1203 | H27: 1164
A28: Facility Expenses | B28: 1291 | C28: 1278 | D28: 906 | E28: 729 | F28: 785 | G28: 1003 | H28: 1174
A29: Travel | B29: 941 | C29: 1140 | D29: 1004 | E29: 198 | F29: 294 | G29: 861 | H29: 913
A30: Communication | B30: 269 | C30: 338 | D30: 360 | E30: 462 | F30: 514 | G30: 745 | H30: 788
A31: Other Costs | B31: 1559 | C31: 2170 | D31: 2053 | E31: 1551 | F31: 1882 | G31: 1934 | H31: 2112
A32: Total Operating Expenses | B32: 21314 | C32: 23855 | D32: 26047 | E32: 24558 | F32: 28680 | G32: 34953 | H32: 37987
B33: 0 | C33: 0 | D33: 0 | E33: 0 | F33: 0 | G33: 0 | H33: 0
A34: Operating Income | B34: 30502 | C34: 37450 | D34: 38580 | E34: 42481 | F34: 48453 | G34: 54237 | H34: 59311
B35: 0 | C35: 0 | D35: 0 | E35: 0 | F35: 0 | G35: 0 | H35: 0
A36: Total Other Income/(Expense) | B36: 3590 | C36: 4113 | D36: 3668 | E36: 2497 | F36: 3234 | G36: 2670 | H36: 3727
B37: 0 | C37: 0 | D37: 0 | E37: 0 | F37: 0 | G37: 0 | H37: 0
A38: Income Before Income Taxes | B38: 34092 | C38: 41563 | D38: 42248 | E38: 44978 | F38: 51687 | G38: 56907 | H38: 63038
B39: 0 | C39: 0 | D39: 0 | E39: 0 | F39: 0 | G39: 0 | H39: 0
A40: Total Taxes | B40: 8212 | C40: 10001 | D40: 9801 | E40: 11458 | F40: 13238 | G40: 14604 | H40: 16262
...

Sheet Ratios
B8: 3-Step DuPont Analysis
B10: All figures in INR Crores unless stated | J10: 2019 | K10: 2020 | L10: 2021 | M10: 2022 | N10: 2023 | O10: 2024 | Q10: Trend
B12: Net Profit Margin | D12: = | E12: Net Income | H12: = | J12: ='Financial Statements'!J36/'Financial Statements'!J12 -> 0.21488021 | K12: ='Financial Statements'!K36/'Financial Statements'!K12 -> 0.2060542 | L12: ='Financial Statements'!L36/'Financial Statements'!L12 -> 0.20336588 | M12: ='Financial Statements'!M36/'Financial Statements'!M12 -> 0.19987588 | N12: ='Financial Statements'!N36/'Financial Statements'!N12 -> 0.18693947 | O12: ='Financial Statements'!O36/'Financial Statements'!O12 -> 0.19338461
E13: Revenue
B15: Asset Turnover | D15: = | E15: Revenue | H15: = | J15: ='Financial Statements'!J12 / 'Financial Statements'!J97 -> 1.2512537 | K15: ='Financial Statements'!K12 / 'Financial Statements'!K97 -> 1.2758733 | L15: ='Financial Statements'!L12 / 'Financial Statements'!L97 -> 1.235519 | M15: ='Financial Statements'!M12 / 'Financial Statements'!M97 -> 1.3350182 | N15: ='Financial Statements'!N12 / 'Financial Statements'!N97 -> 1.54668 | O15: ='Financial Statements'!O12 / 'Financial Statements'!O97 -> 1.621389
E16: Total Assets
B18: Equity Multiplier | D18: = | E18: Total Assets | H18: = | J18: ='Financial Statements'!J97 / 'Financial Statements'!J117 -> 1.2721908 | K18: ='Financial Statements'!K97 / 'Financial Statements'!K117 -> 1.4161726 | L18: ='Financial Statements'!L97 / 'Financial Statements'!L117 -> 1.4891965 | M18: ='Financial Statements'!M97 / 'Financial Statements'!M117 -> 1.5618163 | N18: ='Financial Statements'!N97 / 'Financial Statements'!N117 -> 1.5619669 | O18: ='Financial Statements'!O97 / 'Financial Statements'!O117 -> 1.5899917
E19: Total Shareholders' Equity
B23: 5-Step DuPont Analysis
B25: All figures in INR Crores unless stated | J25: 2019 | K25: 2020 | L25: 2021 | M25: 2022 | N25: 2023 | O25: 2024 | Q25: Trend
B27: Tax Burden | D27: = | E27: Net Income | H27: = | J27: ='Financial Statements'!J36/'Financial Statements'!J29 -> 0.75885516 | K27: ='Financial Statements'!K36/'Financial Statements'!K29 -> 0.76742365 | L27: ='Financial Statements'!L36/'Financial Statements'!L29 -> 0.74450341 | M27: ='Financial Statements'!M36/'Financial Statements'!M29 -> 0.74327548 | N27: ='Financial Statements'!N36/'Financial Statements'!N29 -> 0.74266533 | O27: ='Financial Statements'!O36/'Financial Statements'!O29 -> 0.74124461
E28: Earnings Before Tax
B30: Interest Burden | D30: = | E30: Earnings Before Tax | H30: = | J30: ='Financial Statements'!J29 / 'Financial Statements'!J23 -> 0.99783461 | K30: ='Financial Statements'!K29 / 'Financial Statements'!K23 -> 0.99746734 | L30: ='Financial Statements'!L29 / 'Financial Statements'!L23 -> 0.99706523 | M30: ='Financial Statements'!M29 / 'Financial Statements'!M23 -> 0.99763964 | N30: ='Financial Statements'!N29 / 'Financial Statements'!N23 -> 0.99725869 | O30: ='Financial Statements'!O29 / 'Financial Statements'!O23 -> 0.99697008
E31: EBIT
B33: EBIT Margin | D33: = | E33: EBIT | H33: = | J33: ='Financial Statements'!J23 / 'Financial Statements'!J12 -> 0.28377816 | K33: ='Financial Statements'!K23 / 'Financial Statements'!K12 -> 0.26918298 | L33: ='Financial Statements'!L23 / 'Financial Statements'!L12 -> 0.27396042 | M33: ='Financial Statements'!M23 / 'Financial Statements'!M12 -> 0.26954848 | N33: ='Financial Statements'!N23 / 'Financial Statements'!N12 -> 0.25240621 | O33: ='Financial Statements'!O23 / 'Financial Statements'!O12 -> 0.26168465
E34: Revenue
B36: Asset Turnover | D36: = | E36: Revenue | H36: = | J36: ='Financial Statements'!J12 / 'Financial Statements'!J97 -> 1.2512537 | K36: ='Financial Statements'!K12 / 'Financial Statements'!K97 -> 1.2758733 | L36: ='Financial Statements'!L12 / 'Financial Statements'!L97 -> 1.235519 | M36: ='Financial Statements'!M12 / 'Financial Statements'!M97 -> 1.3350182 | N36: ='Financial Statements'!N12 / 'Financial Statements'!N97 -> 1.54668 | O36: ='Financial Statements'!O12 / 'Financial Statements'!O97 -> 1.621389
E37: Total Assets
B39: Equity Multiplier | D39: = | E39: Total Assets | H39: = | J39: ='Financial Statements'!J97 / 'Financial Statements'!J117 -> 1.2721908 | K39: ='Financial Statements'!K97 / 'Financial Statements'!K117 -> 1.4161726 | L39: ='Financial Statements'!L97 / 'Financial Statements'!L117 -> 1.4891965 | M39: ='Financial Statements'!M97 / 'Financial Statements'!M117 -> 1.5618163 | N39: ='Financial Statements'!N97 / 'Financial Statements'!N117 -> 1.5619669 | O39: ='Financial Statements'!O97 / 'Financial Statements'!O117 -> 1.5899917
E40: Total Shareholders' Equity

Sheet 3-Step DuPont
L8: Return On Equity
J9: 2019 | K9: 2020 | L9: 2021 | M9: 2022 | N9: 2023 | O9: 2024
J10: =B17 * J17 * R17 -> 0.34205349 | K10: =C17 * K17 * S17 -> 0.37231042 | L10: =D17 * L17 * T17 -> 0.37417909 | M10: =E17 * M17 * U17 -> 0.41675184 | N10: =F17 * N17 * V17 -> 0.45162016 | O10: =G17 * O17 * W17 -> 0.49854455
D15: =Ratios!$B$12 -> Net Profit Margin | L15: =Ratios!B15 -> Asset Turnover | T15: =Ratios!B18 -> Equity Multiplier
B16: 2019 | C16: 2020 | D16: 2021 | E16: 2022 | F16: 2023 | G16: 2024 | J16: 2019 | K16: 2020 | L16: 2021 | M16: 2022 | N16: 2023 | O16: 2024 | R16: 2019 | S16: 2020 | T16: 2021 | U16: 2022 | V16: 2023 | W16: 2024
B17: =Ratios!J12 -> 0.21488021 | C17: =Ratios!K12 -> 0.2060542 | D17: =Ratios!L12 -> 0.20336588 | E17: =Ratios!M12 -> 0.19987588 | F17: =Ratios!N12 -> 0.18693947 | G17: =Ratios!O12 -> 0.19338461 | J17: =Ratios!J15 -> 1.2512537 | K17: =Ratios!K15 -> 1.2758733 | L17: =Ratios!L15 -> 1.235519 | M17: =Ratios!M15 -> 1.3350182 | N17: =Ratios!N15 -> 1.54668 | O17: =Ratios!O15 -> 1.621389 | R17: =Ratios!J18 -> 1.2721908 | S17: =Ratios!K18 -> 1.4161726 | T17: =Ratios!L18 -> 1.4891965 | U17: =Ratios!M18 -> 1.5618163 | V17: =Ratios!N18 -> 1.5619669 | W17: =Ratios!O18 -> 1.5899917

Sheet 5-Step DuPont
L7: Return On Equity
J8: 2019 | K8: 2020 | L8: 2021 | M8: 2022 | N8: 2023 | O8: 2024
J9: =B16*F24*J16*N24*R16 -> 0.34205349 | K9: =C16*G24*K16*O24*S16 -> 0.37231042 | L9: =D16*H24*L16*P24*T16 -> 0.37417909 | M9: =E16*I24*M16*Q24*U16 -> 0.41675184 | N9: =F16*J24*N16*R24*V16 -> 0.45162016 | O9: =G16*K24*O16*S24*W16 -> 0.49854455
D14: =Ratios!B27 -> Tax Burden | L14: =Ratios!B33 -> EBIT Margin | T14: =Ratios!B39 -> Equity Multiplier
B15: 2019 | C15: 2020 | D15: 2021 | E15: 2022 | F15: 2023 | G15: 2024 | J15: 2019 | K15: 2020 | L15: 2021 | M15: 2022 | N15: 2023 | O15: 2024 | R15: 2019 | S15: 2020 | T15: 2021 | U15: 2022 | V15: 2023 | W15: 2024
B16: =Ratios!J27 -> 0.75885516 | C16: =Ratios!K27 -> 0.76742365 | D16: =Ratios!L27 -> 0.74450341 | E16: =Ratios!M27 -> 0.74327548 | F16: =Ratios!N27 -> 0.74266533 | G16: =Ratios!O27 -> 0.74124461 | J16: =Ratios!J33 -> 0.28377816 | K16: =Ratios!K33 -> 0.26918298 | L16: =Ratios!L33 -> 0.27396042 | M16: =Ratios!M33 -> 0.26954848 | N16: =Ratios!N33 -> 0.25240621 | O16: =Ratios!O33 -> 0.26168465 | R16: =Ratios!J39 -> 1.2721908 | S16: =Ratios!K39 -> 1.4161726 | T16: =Ratios!L39 -> 1.4891965 | U16: =Ratios!M39 -> 1.5618163 | V16: =Ratios!N39 -> 1.5619669 | W16: =Ratios!O39 -> 1.5899917
H22: =Ratios!B30 -> Interest Burden | P22: =Ratios!B36 -> Asset Turnover
F23: 2019 | G23: 2020 | H23: 2021 | I23: 2022 | J23: 2023 | K23: 2024 | N23: 2019 | O23: 2020 | P23: 2021 | Q23: 2022 | R23: 2023 | S23: 2024
F24: =Ratios!J30 -> 0.99783461 | G24: =Ratios!K30 -> 0.99746734 | H24: =Ratios!L30 -> 0.99706523 | I24: =Ratios!M30 -> 0.99763964 | J24: =Ratios!N30 -> 0.99725869 | K24: =Ratios!O30 -> 0.99697008 | N24: =Ratios!J36 -> 1.2512537 | O24: =Ratios!K36 -> 1.2758733 | P24: =Ratios!L36 -> 1.235519 | Q24: =Ratios!M36 -> 1.3350182 | R24: =Ratios!N36 -> 1.54668 | S24: =Ratios!O36 -> 1.621389
